Workbook

Sheet resultats_comparatifs 
A1: Match_No | B1: NousFinal_Score | C1: NousFinal_Rang | D1: NousdeBase_Score | E1: NousdeBase_Rang | F1: Score3 | G1: Rang3 | H1: Score4 | I1: Rang4 | J1: Nb_Manilles1 | K1: Nb_Manilles2 | L1: Nb_Manilles3 | M1: Nb_Manilles4 | N1: Nb_Moulins_Pris1 | O1: Nb_Moulins_Pris2 | P1: Nb_Moulins_Pris3 | Q1: Nb_Moulins_Pris4
A2: 1 | B2: 6239 | C2: 2 | D2: 5912 | E2: 3 | F2: 2989 | G2: 4 | H2: 6749 | I2: 1 | J2: 8 | K2: 6 | L2: 7 | M2: 5 | N2: 130 | O2: 163 | P2: 153 | Q2: 148
A3: 2 | B3: 5687 | C3: 3 | D3: 5812 | E3: 2 | F3: 4949 | G3: 4 | H3: 5842 | I3: 1 | J3: 2 | K3: 4 | L3: 1 | M3: 9 | N3: 150 | O3: 133 | P3: 123 | Q3: 136
A4: 3 | B4: 5673 | C4: 2 | D4: 5699 | E4: 1 | F4: 3936 | G4: 4 | H4: 4260 | I4: 3 | J4: 8 | K4: 8 | L4: 10 | M4: 7 | N4: 191 | O4: 160 | P4: 146 | Q4: 182
A5: 4 | B5: 5730 | C5: 4 | D5: 5740 | E5: 3 | F5: 5782 | G5: 2 | H5: 6078 | I5: 1 | J5: 3 | K5: 5 | L5: 7 | M5: 5 | N5: 126 | O5: 125 | P5: 114 | Q5: 124
A6: 5 | B6: 12881 | C6: 1 | D6: 998 | E6: 3 | F6: 4253 | G6: 2 | H6: 503 | I6: 4 | J6: 9 | K6: 1 | L6: 8 | M6: 1 | N6: 171 | O6: 18 | P6: 150 | Q6: 18
A7: 6 | B7: 5615 | C7: 1 | D7: 5262 | E7: 2 | F7: 4600 | G7: 4 | H7: 4923 | I7: 3 | J7: 4 | K7: 11 | L7: 6 | M7: 10 | N7: 166 | O7: 151 | P7: 141 | Q7: 171
A8: 7 | B8: 778 | C8: 4 | D8: 1755 | E8: 3 | F8: 5273 | G8: 2 | H8: 7013 | I8: 1 | J8: 1 | K8: 1 | L8: 1 | M8: 1 | N8: 20 | O8: 39 | P8: 42 | Q8: 52
A9: 8 | B9: 11300 | C9: 1 | D9: 1112 | E9: 3 | F9: 200 | G9: 4 | H9: 10108 | I9: 2 | J9: 2 | K9: 0 | L9: 4 | M9: 2 | N9: 134 | O9: 13 | P9: 14 | Q9: 122
A10: 9 | B10: 2935 | C10: 2 | D10: 3169 | E10: 1 | F10: 1701 | G10: 3 | H10: 148 | I10: 4 | J10: 3 | K10: 0 | L10: 2 | M10: 0 | N10: 41 | O10: 7 | P10: 45 | Q10: 10
A11: 10 | B11: 153 | C11: 4 | D11: 353 | E11: 2 | F11: 6382 | G11: 1 | H11: 232 | I11: 3 | J11: 2 | K11: 2 | L11: 0 | M11: 1 | N11: 15 | O11: 22 | P11: 11 | Q11: 10
A12: 11 | B12: 6395 | C12: 2 | D12: 1376 | E12: 4 | F12: 6498 | G12: 1 | H12: 2970 | I12: 3 | J12: 7 | K12: 7 | L12: 5 | M12: 6 | N12: 180 | O12: 157 | P12: 189 | Q12: 108
A13: 12 | B13: 3393 | C13: 3 | D13: 5744 | E13: 1 | F13: 4506 | G13: 2 | H13: 2850 | I13: 4 | J13: 0 | K13: 1 | L13: 0 | M13: 1 | N13: 351 | O13: 336 | P13: 329 | Q13: 358
... A201: 200 | B201: 7225 | C201: 1 | D201: 4605 | E201: 3 | F201: 1785 | G201: 4 | H201: 5066 | I201: 2 | J201: 11 | K201: 9 | L201: 14 | M201: 14 | N201: 114 | O201: 99 | P201: 87 | Q201: 102

Sheet Stats et dashboard
A1: Moyenne Score :
A2: Notre Strat | B2: Strat 2 | C2: Strat 3 | D2: Strat 4
A3: =AVERAGE('resultats_comparatifs '!B:B) -> 6194.925 | B3: =AVERAGE('resultats_comparatifs '!D:D) -> 3767.355 | C3: =AVERAGE('resultats_comparatifs '!F:F) -> 4630.89 | D3: =AVERAGE('resultats_comparatifs '!H:H) -> 4310.725
A5: Moyenne Classement :
A6: Notre Strat | B6: Strat 2 | C6: Strat 3 | D6: Strat 4
A7: =AVERAGE('resultats_comparatifs '!C:C) -> 1.915 | B7: =AVERAGE('resultats_comparatifs '!E:E) -> 2.745 | C7: =AVERAGE('resultats_comparatifs '!G:G) -> 2.74 | D7: =AVERAGE('resultats_comparatifs '!I:I) -> 2.6
A9: Score Moyen par tour :
A10: Notre Strat | B10: Strat 2 | C10: Strat 3 | D10: Strat 4
A11: =A3/1000 -> 6.194925 | B11: =B3/1000 -> 3.767355 | C11: =C3/1000 -> 4.63089 | D11: =D3/1000 -> 4.310725
A13: Taux 1 ere place :
A14: Notre Strat | B14: Strat 2 | C14: Strat 3 | D14: Strat 4
A15: =COUNTIF('resultats_comparatifs '!C:C, 1) / (COUNTA('resultats_comparatifs '!C:C)-1) -> 0.43 | B15: =COUNTIF('resultats_comparatifs '!E:E, 1) / (COUNTA('resultats_comparatifs '!E:E)-1) -> 0.165 | C15: =COUNTIF('resultats_comparatifs '!G:G, 1) / (COUNTA('resultats_comparatifs '!G:G)-1) -> 0.21 | D15: =COUNTIF('resultats_comparatifs '!I:I, 1) / (COUNTA('resultats_comparatifs '!I:I)-1) -> 0.195 | E15: =SUM(A15:D15) -> 1
A18: Taux 2 eme place :
A19: Notre Strat | B19: Strat 2 | C19: Strat 3 | D19: Strat 4
A20: =COUNTIF('resultats_comparatifs '!C:C, 2) / (COUNTA('resultats_comparatifs '!C:C)-1) -> 0.32 | B20: =COUNTIF('resultats_comparatifs '!E:E, 2) / (COUNTA('resultats_comparatifs '!E:E)-1) -> 0.2 | C20: =COUNTIF('resultats_comparatifs '!G:G, 2) / (COUNTA('resultats_comparatifs '!G:G)-1) -> 0.21 | D20: =COUNTIF('resultats_comparatifs '!I:I, 2) / (COUNTA('resultats_comparatifs '!I:I)-1) -> 0.27 | E20: =SUM(A20:D20) -> 1
A23: Taux 3 eme place :
A24: Notre Strat | B24: Strat 2 | C24: Strat 3 | D24: Strat 4
A25: =COUNTIF('resultats_comparatifs '!C:C, 3) / (COUNTA('resultats_comparatifs '!C:C)-1) -> 0.155 | B25: =COUNTIF('resultats_comparatifs '!E:E, 3) / (COUNTA('resultats_comparatifs '!E:E)-1) -> 0.36 | C25: =COUNTIF('resultats_comparatifs '!G:G, 3) / (COUNTA('resultats_comparatifs '!G:G)-1) -> 0.21 | D25: =COUNTIF('resultats_comparatifs '!I:I, 3) / (COUNTA('resultats_comparatifs '!I:I)-1) -> 0.275 | E25: =SUM(A25:D25) -> 1
A29: Taux 4 eme place :
A30: Notre Strat | B30: Strat 2 | C30: Strat 3 | D30: Strat 4
A31: =COUNTIF('resultats_comparatifs '!C:C, 4) / (COUNTA('resultats_comparatifs '!C:C)-1) -> 0.095 | B31: =COUNTIF('resultats_comparatifs '!E:E, 4) / (COUNTA('resultats_comparatifs '!E:E)-1) -> 0.275 | C31: =COUNTIF('resultats_comparatifs '!G:G, 4) / (COUNTA('resultats_comparatifs '!G:G)-1) -> 0.37 | D31: =COUNTIF('resultats_comparatifs '!I:I, 4) / (COUNTA('resultats_comparatifs '!I:I)-1) -> 0.26 | E31: =SUM(A31:D31) -> 1
A33: Total de bouteilles d'huile :
A34: Notre Strat | B34: Strat 2 | C34: Strat 3 | D34: Strat 4
A35: =SUM('resultats_comparatifs '!B:B) -> 1238985 | B35: =SUM('resultats_comparatifs '!D:D) -> 753471 | C35: =SUM('resultats_comparatifs '!F:F) -> 926178 | D35: =SUM('resultats_comparatifs '!H:H) -> 862145
A37: Moyenne manilles
A38: Notre Strat | B38: Strat 2 | C38: Strat 3 | D38: Strat 4
A39: =AVERAGE('resultats_comparatifs '!J:J) -> 7.01 | B39: =AVERAGE('resultats_comparatifs '!K:K) -> 6.55 | C39: =AVERAGE('resultats_comparatifs '!L:L) -> 6.495 | D39: =AVERAGE('resultats_comparatifs '!M:M) -> 7.08

Sheet resultats_exploitables
A1: Match_No | B1: Stratégie | C1: Score | D1: Rang | E1: Nb Manilles | F1: Nb Moulins_Pris
A2: 1 | B2: Nous_Final | C2: 6239 | D2: 2 | E2: 8 | F2: 130
A3: 1 | B3: Nous_deBase | C3: 5912 | D3: 3 | E3: 6 | F3: 163
A4: 1 | B4: 3 | C4: 2989 | D4: 4 | E4: 7 | F4: 153
A5: 1 | B5: 4 | C5: 6749 | D5: 1 | E5: 5 | F5: 148
A6: 2 | B6: Nous_Final | C6: 5687 | D6: 3 | E6: 2 | F6: 150
A7: 2 | B7: Nous_deBase | C7: 5812 | D7: 2 | E7: 4 | F7: 133
A8: 2 | B8: 3 | C8: 4949 | D8: 4 | E8: 1 | F8: 123
A9: 2 | B9: 4 | C9: 5842 | D9: 1 | E9: 9 | F9: 136
A10: 3 | B10: Nous_Final | C10: 5673 | D10: 2 | E10: 8 | F10: 191
A11: 3 | B11: Nous_deBase | C11: 5699 | D11: 1 | E11: 8 | F11: 160
A12: 3 | B12: 3 | C12: 3936 | D12: 4 | E12: 10 | F12: 146
A13: 3 | B13: 4 | C13: 4260 | D13: 3 | E13: 7 | F13: 182
A14: 4 | B14: Nous_Final | C14: 5730 | D14: 4 | E14: 3 | F14: 126
A15: 4 | B15: Nous_deBase | C15: 5740 | D15: 3 | E15: 5 | F15: 125
A16: 4 | B16: 3 | C16: 5782 | D16: 2 | E16: 7 | F16: 114
A17: 4 | B17: 4 | C17: 6078 | D17: 1 | E17: 5 | F17: 124
A18: 5 | B18: Nous_Final | C18: 12881 | D18: 1 | E18: 9 | F18: 171
A19: 5 | B19: Nous_deBase | C19: 998 | D19: 3 | E19: 1 | F19: 18
A20: 5 | B20: 3 | C20: 4253 | D20: 2 | E20: 8 | F20: 150
A21: 5 | B21: 4 | C21: 503 | D21: 4 | E21: 1 | F21: 18
A22: 6 | B22: Nous_Final | C22: 5615 | D22: 1 | E22: 4 | F22: 166
A23: 6 | B23: Nous_deBase | C23: 5262 | D23: 2 | E23: 11 | F23: 151
A24: 6 | B24: 3 | C24: 4600 | D24: 4 | E24: 6 | F24: 141
A25: 6 | B25: 4 | C25: 4923 | D25: 3 | E25: 10 | F25: 171
A26: 7 | B26: Nous_Final | C26: 778 | D26: 4 | E26: 1 | F26: 20
A27: 7 | B27: Nous_deBase | C27: 1755 | D27: 3 | E27: 1 | F27: 39
A28: 7 | B28: 3 | C28: 5273 | D28: 2 | E28: 1 | F28: 42
A29: 7 | B29: 4 | C29: 7013 | D29: 1 | E29: 1 | F29: 52
A30: 8 | B30: Nous_Final | C30: 11300 | D30: 1 | E30: 2 | F30: 134
A31: 8 | B31: Nous_deBase | C31: 1112 | D31: 3 | E31: 0 | F31: 13
A32: 8 | B32: 3 | C32: 200 | D32: 4 | E32: 4 | F32: 14
A33: 8 | B33: 4 | C33: 10108 | D33: 2 | E33: 2 | F33: 122
A34: 9 | B34: Nous_Final | C34: 2935 | D34: 2 | E34: 3 | F34: 41
A35: 9 | B35: Nous_deBase | C35: 3169 | D35: 1 | E35: 0 | F35: 7
A36: 9 | B36: 3 | C36: 1701 | D36: 3 | E36: 2 | F36: 45
A37: 9 | B37: 4 | C37: 148 | D37: 4 | E37: 0 | F37: 10
A38: 10 | B38: Nous_Final | C38: 153 | D38: 4 | E38: 2 | F38: 15
A39: 10 | B39: Nous_deBase | C39: 353 | D39: 2 | E39: 2 | F39: 22
A40: 10 | B40: 3 | C40: 6382 | D40: 1 | E40: 0 | F40: 11
...

Sheet Tableau dynamique
A3: Étiquettes de lignes | B3: Moyenne de Score | C3: Somme de Score | D3: % Production Huile
A4: 3 | B4: 4630.89 | C4: 926178 | D4: 0.24497015
A5: 4 | B5: 4310.725 | C5: 862145 | D5: 0.22803369
A6: Nous_deBase | B6: 3767.355 | C6: 753471 | D6: 0.19928988
A7: Nous_Final | B7: 6194.925 | C7: 1238985 | D7: 0.32770627
A8: Total général | B8: 4725.9738 | C8: 3780779 | D8: 1
